2025-02-11T17:20:56,106 Using pip 24.0 from /home/kevin/Escritorio/universidad_github/universidad/lib/python3.12/site-packages/pip (python 3.12)
2025-02-11T17:20:56,106 Non-user install because user site-packages disabled
2025-02-11T17:20:56,136 Created temporary directory: /tmp/pip-build-tracker-valhy3w3
2025-02-11T17:20:56,136 Initialized build tracking at /tmp/pip-build-tracker-valhy3w3
2025-02-11T17:20:56,136 Created build tracker: /tmp/pip-build-tracker-valhy3w3
2025-02-11T17:20:56,136 Entered build tracker: /tmp/pip-build-tracker-valhy3w3
2025-02-11T17:20:56,136 Created temporary directory: /tmp/pip-install-9ayc0cqv
2025-02-11T17:20:56,138 Created temporary directory: /tmp/pip-ephem-wheel-cache-jnd3leg5
2025-02-11T17:20:56,143 1 location(s) to search for versions of freeze:
2025-02-11T17:20:56,143 * https://pypi.org/simple/freeze/
2025-02-11T17:20:56,143 Fetching project page and analyzing links: https://pypi.org/simple/freeze/
2025-02-11T17:20:56,143 Getting page https://pypi.org/simple/freeze/
2025-02-11T17:20:56,143 Found index url https://pypi.org/simple/
2025-02-11T17:20:56,531 Could not fetch URL https://pypi.org/simple/freeze/: 404 Client Error: Not Found for url: https://pypi.org/simple/freeze/ - skipping
2025-02-11T17:20:56,531 Skipping link: not a file: https://pypi.org/simple/freeze/
2025-02-11T17:20:56,539 Given no hashes to check 0 links for project 'freeze': discarding no candidates
2025-02-11T17:20:56,539 ERROR: Could not find a version that satisfies the requirement freeze (from versions: none)
2025-02-11T17:20:56,540 ERROR: No matching distribution found for freeze
2025-02-11T17:20:56,540 Exception information:
2025-02-11T17:20:56,540 Traceback (most recent call last):
2025-02-11T17:20:56,540   File "/home/kevin/Escritorio/universidad_github/universidad/lib/python3.12/site-packages/pip/_vendor/resolvelib/resolvers.py", line 397, in resolve
2025-02-11T17:20:56,540     self._add_to_criteria(self.state.criteria, r, parent=None)
2025-02-11T17:20:56,540   File "/home/kevin/Escritorio/universidad_github/universidad/lib/python3.12/site-packages/pip/_vendor/resolvelib/resolvers.py", line 174, in _add_to_criteria
2025-02-11T17:20:56,540     raise RequirementsConflicted(criterion)
2025-02-11T17:20:56,540 pip._vendor.resolvelib.resolvers.RequirementsConflicted: Requirements conflict: SpecifierRequirement('freeze')
2025-02-11T17:20:56,540 
2025-02-11T17:20:56,540 During handling of the above exception, another exception occurred:
2025-02-11T17:20:56,540 
2025-02-11T17:20:56,540 Traceback (most recent call last):
2025-02-11T17:20:56,540   File "/home/kevin/Escritorio/universidad_github/universidad/lib/python3.12/site-packages/pip/_internal/resolution/resolvelib/resolver.py", line 95, in resolve
2025-02-11T17:20:56,540     result = self._result = resolver.resolve(
2025-02-11T17:20:56,540                             ^^^^^^^^^^^^^^^^^
2025-02-11T17:20:56,540   File "/home/kevin/Escritorio/universidad_github/universidad/lib/python3.12/site-packages/pip/_vendor/resolvelib/resolvers.py", line 546, in resolve
2025-02-11T17:20:56,540     state = resolution.resolve(requirements, max_rounds=max_rounds)
2025-02-11T17:20:56,540             ^^^^^^^^^^^^^^^^^^^^^^^^^^^^^^^^^^^^^^^^^^^^^^^^^^^^^^^
2025-02-11T17:20:56,540   File "/home/kevin/Escritorio/universidad_github/universidad/lib/python3.12/site-packages/pip/_vendor/resolvelib/resolvers.py", line 399, in resolve
2025-02-11T17:20:56,540     raise ResolutionImpossible(e.criterion.information)
2025-02-11T17:20:56,540 pip._vendor.resolvelib.resolvers.ResolutionImpossible: [RequirementInformation(requirement=SpecifierRequirement('freeze'), parent=None)]
2025-02-11T17:20:56,540 
2025-02-11T17:20:56,540 The above exception was the direct cause of the following exception:
2025-02-11T17:20:56,540 
2025-02-11T17:20:56,540 Traceback (most recent call last):
2025-02-11T17:20:56,540   File "/home/kevin/Escritorio/universidad_github/universidad/lib/python3.12/site-packages/pip/_internal/cli/base_command.py", line 180, in exc_logging_wrapper
2025-02-11T17:20:56,540     status = run_func(*args)
2025-02-11T17:20:56,540              ^^^^^^^^^^^^^^^
2025-02-11T17:20:56,540   File "/home/kevin/Escritorio/universidad_github/universidad/lib/python3.12/site-packages/pip/_internal/cli/req_command.py", line 245, in wrapper
2025-02-11T17:20:56,540     return func(self, options, args)
2025-02-11T17:20:56,540            ^^^^^^^^^^^^^^^^^^^^^^^^^
2025-02-11T17:20:56,540   File "/home/kevin/Escritorio/universidad_github/universidad/lib/python3.12/site-packages/pip/_internal/commands/install.py", line 377, in run
2025-02-11T17:20:56,540     requirement_set = resolver.resolve(
2025-02-11T17:20:56,540                       ^^^^^^^^^^^^^^^^^
2025-02-11T17:20:56,540   File "/home/kevin/Escritorio/universidad_github/universidad/lib/python3.12/site-packages/pip/_internal/resolution/resolvelib/resolver.py", line 104, in resolve
2025-02-11T17:20:56,540     raise error from e
2025-02-11T17:20:56,540 pip._internal.exceptions.DistributionNotFound: No matching distribution found for freeze
2025-02-11T17:20:56,542 Removed build tracker: '/tmp/pip-build-tracker-valhy3w3'
